{
 "PRed":[
  {
   "data":{
    "bot_rerun":false,
    "migrator_name":"Version",
    "migrator_version":0,
    "version":"0.13"
   },
   "keys":[
    "bot_rerun",
    "migrator_name",
    "migrator_version",
    "version"
   ]
  },
  {
   "PR":{
    "__lazy_json__":"pr_json/235258088.json"
   },
   "data":{
    "bot_rerun":false,
    "migrator_name":"Version",
    "migrator_version":0,
    "version":"0.14"
   },
   "keys":[
    "bot_rerun",
    "migrator_name",
    "migrator_version",
    "version"
   ]
  }
 ],
 "bad":{
  "exception":"<class 'requests.exceptions.ReadTimeout'>: A connection-level exception occurred: HTTPSConnectionPool(host='api.github.com', port=443): Read timed out. (read timeout=10)",
  "traceback":[
   "Traceback (most recent call last):",
   "  File \"/opt/conda/envs/run_env/lib/python3.8/site-packages/urllib3/connectionpool.py\", line 421, in _make_request",
   "    six.raise_from(e, None)",
   "  File \"<string>\", line 3, in raise_from",
   "  File \"/opt/conda/envs/run_env/lib/python3.8/site-packages/urllib3/connectionpool.py\", line 416, in _make_request",
   "    httplib_response = conn.getresponse()",
   "  File \"/opt/conda/envs/run_env/lib/python3.8/http/client.py\", line 1322, in getresponse",
   "    response.begin()",
   "  File \"/opt/conda/envs/run_env/lib/python3.8/http/client.py\", line 303, in begin",
   "    version, status, reason = self._read_status()",
   "  File \"/opt/conda/envs/run_env/lib/python3.8/http/client.py\", line 264, in _read_status",
   "    line = str(self.fp.readline(_MAXLINE + 1), \"iso-8859-1\")",
   "  File \"/opt/conda/envs/run_env/lib/python3.8/socket.py\", line 669, in readinto",
   "    return self._sock.recv_into(b)",
   "  File \"/opt/conda/envs/run_env/lib/python3.8/site-packages/urllib3/contrib/pyopenssl.py\", line 326, in recv_into",
   "    raise timeout(\"The read operation timed out\")",
   "socket.timeout: The read operation timed out",
   "",
   "During handling of the above exception, another exception occurred:",
   "",
   "Traceback (most recent call last):",
   "  File \"/opt/conda/envs/run_env/lib/python3.8/site-packages/requests/adapters.py\", line 439, in send",
   "    resp = conn.urlopen(",
   "  File \"/opt/conda/envs/run_env/lib/python3.8/site-packages/urllib3/connectionpool.py\", line 719, in urlopen",
   "    retries = retries.increment(",
   "  File \"/opt/conda/envs/run_env/lib/python3.8/site-packages/urllib3/util/retry.py\", line 400, in increment",
   "    raise six.reraise(type(error), error, _stacktrace)",
   "  File \"/opt/conda/envs/run_env/lib/python3.8/site-packages/urllib3/packages/six.py\", line 735, in reraise",
   "    raise value",
   "  File \"/opt/conda/envs/run_env/lib/python3.8/site-packages/urllib3/connectionpool.py\", line 665, in urlopen",
   "    httplib_response = self._make_request(",
   "  File \"/opt/conda/envs/run_env/lib/python3.8/site-packages/urllib3/connectionpool.py\", line 423, in _make_request",
   "    self._raise_timeout(err=e, url=url, timeout_value=read_timeout)",
   "  File \"/opt/conda/envs/run_env/lib/python3.8/site-packages/urllib3/connectionpool.py\", line 330, in _raise_timeout",
   "    raise ReadTimeoutError(",
   "urllib3.exceptions.ReadTimeoutError: HTTPSConnectionPool(host='api.github.com', port=443): Read timed out. (read timeout=10)",
   "",
   "During handling of the above exception, another exception occurred:",
   "",
   "Traceback (most recent call last):",
   "  File \"/opt/conda/envs/run_env/lib/python3.8/site-packages/github3/models.py\", line 196, in _request",
   "    return request_method(*args, **kwargs)",
   "  File \"/opt/conda/envs/run_env/lib/python3.8/site-packages/requests/sessions.py\", line 546, in get",
   "    return self.request('GET', url, **kwargs)",
   "  File \"/opt/conda/envs/run_env/lib/python3.8/site-packages/github3/session.py\", line 169, in request",
   "    response = super(GitHubSession, self).request(*args, **kwargs)",
   "  File \"/opt/conda/envs/run_env/lib/python3.8/site-packages/requests/sessions.py\", line 533, in request",
   "    resp = self.send(prep, **send_kwargs)",
   "  File \"/opt/conda/envs/run_env/lib/python3.8/site-packages/requests/sessions.py\", line 646, in send",
   "    r = adapter.send(request, **kwargs)",
   "  File \"/opt/conda/envs/run_env/lib/python3.8/site-packages/requests/adapters.py\", line 529, in send",
   "    raise ReadTimeout(e, request=request)",
   "requests.exceptions.ReadTimeout: HTTPSConnectionPool(host='api.github.com', port=443): Read timed out. (read timeout=10)",
   "",
   "During handling of the above exception, another exception occurred:",
   "",
   "Traceback (most recent call last):",
   "  File \"/root/repo/cf-scripts/conda_forge_tick/auto_tick.py\", line 647, in main",
   "    or mctx.gh.rate_limit()[\"resources\"][\"core\"][\"remaining\"] == 0",
   "  File \"/opt/conda/envs/run_env/lib/python3.8/site-packages/github3/github.py\", line 1867, in rate_limit",
   "    return self._json(self._get(url), 200)",
   "  File \"/opt/conda/envs/run_env/lib/python3.8/site-packages/github3/models.py\", line 211, in _get",
   "    return self._request(\"get\", url, **kwargs)",
   "  File \"/opt/conda/envs/run_env/lib/python3.8/site-packages/github3/models.py\", line 201, in _request",
   "    raise exceptions.ConnectionError(exc)",
   "github3.exceptions.ConnectionError: <class 'requests.exceptions.ReadTimeout'>: A connection-level exception occurred: HTTPSConnectionPool(host='api.github.com', port=443): Read timed out. (read timeout=10)",
   ""
  ]
 },
 "conda-forge.yml":{},
 "feedstock_name":"djangorestframework-gis",
 "hash_type":"sha256",
 "meta_yaml":{
  "about":{
   "dev_url":"https://github.com/djangonauts/django-rest-framework-gis",
   "doc_url":"https://github.com/djangonauts/django-rest-framework-gis",
   "home":"https://github.com/djangonauts/django-rest-framework-gis",
   "license":"MIT",
   "license_family":"MIT",
   "license_file":"LICENSE",
   "summary":"Geographic add-ons for Django Rest Framework"
  },
  "build":{
   "noarch":"python",
   "number":"0",
   "script":" -m pip install . --no-deps -vv"
  },
  "extra":{
   "recipe-maintainers":[
    "kwilcox",
    "ocefpaf",
    "kwilcox",
    "ocefpaf",
    "kwilcox",
    "ocefpaf"
   ]
  },
  "package":{
   "name":"djangorestframework-gis",
   "version":"0.14"
  },
  "requirements":{
   "build":[
    "python >=3",
    "pip",
    "djangorestframework",
    "python >=3",
    "pip",
    "djangorestframework",
    "python >=3",
    "pip",
    "djangorestframework"
   ],
   "run":[
    "python >=3",
    "djangorestframework",
    "python >=3",
    "djangorestframework",
    "python >=3",
    "djangorestframework"
   ]
  },
  "source":{
   "sha256":"e645c6c8aedee53ac0a4851abcdf8121fff66813eebae1b040b1ccb941cb248b",
   "url":"https://pypi.io/packages/source/d/djangorestframework-gis/djangorestframework-gis-0.14.tar.gz"
  },
  "test":{
   "imports":[
    "rest_framework_gis",
    "rest_framework_gis",
    "rest_framework_gis"
   ]
  }
 },
 "name":"djangorestframework-gis",
 "new_version":"0.15",
 "pinning_version":"2018.11.27",
 "raw_meta_yaml":"{% set version = \"0.14\" %}\n\npackage:\n  name: djangorestframework-gis\n  version: {{ version }}\n\nsource:\n  url: https://pypi.io/packages/source/d/djangorestframework-gis/djangorestframework-gis-{{ version }}.tar.gz\n  sha256: e645c6c8aedee53ac0a4851abcdf8121fff66813eebae1b040b1ccb941cb248b\n\nbuild:\n  number: 0\n  noarch: python\n  script: \"{{ PYTHON }} -m pip install . --no-deps -vv\"\n\nrequirements:\n  build:\n    - python >=3\n    - pip\n    - djangorestframework\n  run:\n    - python >=3\n    - djangorestframework\n\ntest:\n  imports:\n    - rest_framework_gis\n\nabout:\n  home: https://github.com/djangonauts/django-rest-framework-gis\n  summary: 'Geographic add-ons for Django Rest Framework'\n  license: MIT\n  license_family: MIT\n  license_file: LICENSE\n  doc_url: https://github.com/djangonauts/django-rest-framework-gis\n  dev_url: https://github.com/djangonauts/django-rest-framework-gis\n\nextra:\n  recipe-maintainers:\n    - kwilcox\n    - ocefpaf\n",
 "req":{
  "__set__":true,
  "elements":[
   "djangorestframework",
   "pip",
   "python"
  ]
 },
 "smithy_version":"3.1.12",
 "url":"https://pypi.io/packages/source/d/djangorestframework-gis/djangorestframework-gis-0.14.tar.gz",
 "version":"0.14"
}