{
 "exception":"[Errno 36] File name too long: '/opt/conda/envs/run_env/conda-bld/tmps6_4w_kb/pytest-datadir-1.3.1/tests/test_hello/aaaaaaaaaaaaaaaaaaaaaaaaaaaaaaaaaaaaaaaaaaaaaaaaaaaaaaaaaaaaaaaaaaaaaaaaaaaaaaaaaaaaaaaaaaaaaaaaaaaaaaaaaaaaaaaaaaaaaaaaaaaaaaaaaaaaaaaaaaaaaaaaaaaaaaaaaaaaaaaaaaaaaaaaaaaaaaaaaaaaaaaaaaaaaaaaaaaaaaaaaaaaaaaaaaaaaaaaaaaaaaaaaaaaaaaaaaaaaaaaaaaaaaaaaa.txt'",
 "traceback":[
  "Traceback (most recent call last):",
  "  File \"/opt/conda/envs/run_env/lib/python3.7/site-packages/conda_build/utils.py\", line 836, in tar_xf",
  "    libarchive.extract_file(tarball, flags)",
  "  File \"/opt/conda/envs/run_env/lib/python3.7/site-packages/libarchive/extract.py\", line 70, in extract_file",
  "    extract_entries(archive, flags)",
  "  File \"/opt/conda/envs/run_env/lib/python3.7/site-packages/libarchive/extract.py\", line 50, in extract_entries",
  "    write_header(write_p, entry._entry_p)",
  "  File \"/opt/conda/envs/run_env/lib/python3.7/site-packages/libarchive/ffi.py\", line 91, in check_int",
  "    raise archive_error(args[0], retcode)",
  "  File \"/opt/conda/envs/run_env/lib/python3.7/site-packages/libarchive/ffi.py\", line 75, in archive_error",
  "    raise ArchiveError(msg, errno(archive_p), retcode, archive_p)",
  "libarchive.exception.ArchiveError: Could not stat pytest-datadir-1.3.1/tests/test_hello/aaaaaaaaaaaaaaaaaaaaaaaaaaaaaaaaaaaaaaaaaaaaaaaaaaaaaaaaaaaaaaaaaaaaaaaaaaaaaaaaaaaaaaaaaaaaaaaaaaaaaaaaaaaaaaaaaaaaaaaaaaaaaaaaaaaaaaaaaaaaaaaaaaaaaaaaaaaaaaaaaaaaaaaaaaaaaaaaaaaaaaaaaaaaaaaaaaaaaaaaaaaaaaaaaaaaaaaaaaaaaaaaaaaaaaaaaaaaaaaaaaaaaaaaaa.txt (errno=36, retcode=-25, archive_p=94045843474800)",
  "",
  "During handling of the above exception, another exception occurred:",
  "",
  "Traceback (most recent call last):",
  "  File \"/root/repo/cf-scripts/conda_forge_tick/audit.py\", line 265, in main",
  "    deps = v[\"run\"](fctx, ctx, import_map)",
  "  File \"/root/repo/cf-scripts/conda_forge_tick/audit.py\", line 58, in depfinder_audit_feedstock",
  "    cb_work_dir = _get_source_code(recipe_dir)",
  "  File \"/root/repo/cf-scripts/conda_forge_tick/migrators/core.py\", line 68, in _get_source_code",
  "    return provide(md)",
  "  File \"/opt/conda/envs/run_env/lib/python3.7/site-packages/conda_build/source.py\", line 654, in provide",
  "    timeout=metadata.config.timeout, locking=metadata.config.locking)",
  "  File \"/opt/conda/envs/run_env/lib/python3.7/site-packages/conda_build/source.py\", line 148, in unpack",
  "    tar_xf(src_path, tmpdir)",
  "  File \"/opt/conda/envs/run_env/lib/python3.7/site-packages/conda_build/utils.py\", line 842, in tar_xf",
  "    _tar_xf_fallback(tarball, dir_path)",
  "  File \"/opt/conda/envs/run_env/lib/python3.7/site-packages/conda_build/utils.py\", line 790, in _tar_xf_fallback",
  "    t.extractall(path=dir_path)",
  "  File \"/opt/conda/envs/run_env/lib/python3.7/tarfile.py\", line 2000, in extractall",
  "    numeric_owner=numeric_owner)",
  "  File \"/opt/conda/envs/run_env/lib/python3.7/tarfile.py\", line 2042, in extract",
  "    numeric_owner=numeric_owner)",
  "  File \"/opt/conda/envs/run_env/lib/python3.7/tarfile.py\", line 2112, in _extract_member",
  "    self.makefile(tarinfo, targetpath)",
  "  File \"/opt/conda/envs/run_env/lib/python3.7/tarfile.py\", line 2153, in makefile",
  "    with bltn_open(targetpath, \"wb\") as target:",
  "OSError: [Errno 36] File name too long: '/opt/conda/envs/run_env/conda-bld/tmps6_4w_kb/pytest-datadir-1.3.1/tests/test_hello/aaaaaaaaaaaaaaaaaaaaaaaaaaaaaaaaaaaaaaaaaaaaaaaaaaaaaaaaaaaaaaaaaaaaaaaaaaaaaaaaaaaaaaaaaaaaaaaaaaaaaaaaaaaaaaaaaaaaaaaaaaaaaaaaaaaaaaaaaaaaaaaaaaaaaaaaaaaaaaaaaaaaaaaaaaaaaaaaaaaaaaaaaaaaaaaaaaaaaaaaaaaaaaaaaaaaaaaaaaaaaaaaaaaaaaaaaaaaaaaaaaaaaaaaaa.txt'",
  ""
 ]
}