{
 "exception": "('Connection aborted.', OSError(107, 'Transport endpoint is not connected'))",
 "traceback": [
  "Traceback (most recent call last):",
  "  File \"/usr/share/miniconda/envs/run_env/lib/python3.8/site-packages/urllib3/connectionpool.py\", line 670, in urlopen",
  "    httplib_response = self._make_request(",
  "  File \"/usr/share/miniconda/envs/run_env/lib/python3.8/site-packages/urllib3/connectionpool.py\", line 381, in _make_request",
  "    self._validate_conn(conn)",
  "  File \"/usr/share/miniconda/envs/run_env/lib/python3.8/site-packages/urllib3/connectionpool.py\", line 978, in _validate_conn",
  "    conn.connect()",
  "  File \"/usr/share/miniconda/envs/run_env/lib/python3.8/site-packages/urllib3/connection.py\", line 386, in connect",
  "    cert = self.sock.getpeercert()",
  "  File \"/usr/share/miniconda/envs/run_env/lib/python3.8/ssl.py\", line 1123, in getpeercert",
  "    self._check_connected()",
  "  File \"/usr/share/miniconda/envs/run_env/lib/python3.8/ssl.py\", line 1088, in _check_connected",
  "    self.getpeername()",
  "OSError: [Errno 107] Transport endpoint is not connected",
  "",
  "During handling of the above exception, another exception occurred:",
  "",
  "Traceback (most recent call last):",
  "  File \"/usr/share/miniconda/envs/run_env/lib/python3.8/site-packages/requests/adapters.py\", line 439, in send",
  "    resp = conn.urlopen(",
  "  File \"/usr/share/miniconda/envs/run_env/lib/python3.8/site-packages/urllib3/connectionpool.py\", line 726, in urlopen",
  "    retries = retries.increment(",
  "  File \"/usr/share/miniconda/envs/run_env/lib/python3.8/site-packages/urllib3/util/retry.py\", line 410, in increment",
  "    raise six.reraise(type(error), error, _stacktrace)",
  "  File \"/usr/share/miniconda/envs/run_env/lib/python3.8/site-packages/urllib3/packages/six.py\", line 734, in reraise",
  "    raise value.with_traceback(tb)",
  "  File \"/usr/share/miniconda/envs/run_env/lib/python3.8/site-packages/urllib3/connectionpool.py\", line 670, in urlopen",
  "    httplib_response = self._make_request(",
  "  File \"/usr/share/miniconda/envs/run_env/lib/python3.8/site-packages/urllib3/connectionpool.py\", line 381, in _make_request",
  "    self._validate_conn(conn)",
  "  File \"/usr/share/miniconda/envs/run_env/lib/python3.8/site-packages/urllib3/connectionpool.py\", line 978, in _validate_conn",
  "    conn.connect()",
  "  File \"/usr/share/miniconda/envs/run_env/lib/python3.8/site-packages/urllib3/connection.py\", line 386, in connect",
  "    cert = self.sock.getpeercert()",
  "  File \"/usr/share/miniconda/envs/run_env/lib/python3.8/ssl.py\", line 1123, in getpeercert",
  "    self._check_connected()",
  "  File \"/usr/share/miniconda/envs/run_env/lib/python3.8/ssl.py\", line 1088, in _check_connected",
  "    self.getpeername()",
  "urllib3.exceptions.ProtocolError: ('Connection aborted.', OSError(107, 'Transport endpoint is not connected'))",
  "",
  "During handling of the above exception, another exception occurred:",
  "",
  "Traceback (most recent call last):",
  "  File \"/home/runner/work/autotick-bot/autotick-bot/cf-scripts/conda_forge_tick/audit.py\", line 475, in main",
  "    deps = v[\"run\"](fctx, ctx)",
  "  File \"/home/runner/work/autotick-bot/autotick-bot/cf-scripts/conda_forge_tick/audit.py\", line 86, in depfinder_audit_feedstock",
  "    return extract_deps_from_source(recipe_dir)",
  "  File \"/home/runner/work/autotick-bot/autotick-bot/cf-scripts/conda_forge_tick/audit.py\", line 66, in extract_deps_from_source",
  "    for k, v in simple_import_search_conda_forge_import_map(",
  "  File \"/usr/share/miniconda/envs/run_env/lib/python3.8/site-packages/depfinder/main.py\", line 237, in simple_import_search_conda_forge_import_map",
  "    imports, _, _ = report_conda_forge_names_from_import_map(",
  "  File \"/usr/share/miniconda/envs/run_env/lib/python3.8/site-packages/depfinder/reports.py\", line 95, in report_conda_forge_names_from_import_map",
  "    most_likely_pkg, _import_to_artifact, _import_to_pkg = future.result()",
  "  File \"/usr/share/miniconda/envs/run_env/lib/python3.8/concurrent/futures/_base.py\", line 432, in result",
  "    return self.__get_result()",
  "  File \"/usr/share/miniconda/envs/run_env/lib/python3.8/concurrent/futures/_base.py\", line 388, in __get_result",
  "    raise self._exception",
  "  File \"/usr/share/miniconda/envs/run_env/lib/python3.8/concurrent/futures/thread.py\", line 57, in run",
  "    result = self.fn(*self.args, **self.kwargs)",
  "  File \"/usr/share/miniconda/envs/run_env/lib/python3.8/site-packages/depfinder/reports.py\", line 67, in extract_pkg_from_import",
  "    import_map = _import_map_cache(ftl)",
  "  File \"/usr/share/miniconda/envs/run_env/lib/python3.8/site-packages/depfinder/reports.py\", line 52, in _import_map_cache",
  "    return {k: set(v['elements']) for k, v in requests.get(",
  "  File \"/usr/share/miniconda/envs/run_env/lib/python3.8/site-packages/requests/api.py\", line 76, in get",
  "    return request('get', url, params=params, **kwargs)",
  "  File \"/usr/share/miniconda/envs/run_env/lib/python3.8/site-packages/requests/api.py\", line 61, in request",
  "    return session.request(method=method, url=url, **kwargs)",
  "  File \"/usr/share/miniconda/envs/run_env/lib/python3.8/site-packages/requests/sessions.py\", line 542, in request",
  "    resp = self.send(prep, **send_kwargs)",
  "  File \"/usr/share/miniconda/envs/run_env/lib/python3.8/site-packages/requests/sessions.py\", line 655, in send",
  "    r = adapter.send(request, **kwargs)",
  "  File \"/usr/share/miniconda/envs/run_env/lib/python3.8/site-packages/requests/adapters.py\", line 498, in send",
  "    raise ConnectionError(err, request=request)",
  "requests.exceptions.ConnectionError: ('Connection aborted.', OSError(107, 'Transport endpoint is not connected'))",
  ""
 ]
}