exception: "It was not possible to recover PyPi metadata for pymt_child.\nError code:\
  \ 404"
traceback: ['Traceback (most recent call last):', '  File "/home/runner/work/autotick-bot/autotick-bot/cf-scripts/conda_forge_tick/audit.py",
    line 475, in main', '    deps = v["run"](fctx, ctx)', '  File "/home/runner/work/autotick-bot/autotick-bot/cf-scripts/conda_forge_tick/audit.py",
    line 94, in grayskull_audit_feedstock', '    recipe = GrayskullFactory.create_recipe(',
  '  File "/usr/share/miniconda/envs/run_env/lib/python3.8/site-packages/grayskull/base/factory.py",
    line 22, in create_recipe', '    return GrayskullFactory.REGISTERED_CLASS[repo_type.lower()](',
  '  File "/usr/share/miniconda/envs/run_env/lib/python3.8/site-packages/grayskull/pypi/pypi.py",
    line 58, in __init__', '    super(PyPi, self).__init__(name=name, version=str(version)
    if version else None)', '  File "/usr/share/miniconda/envs/run_env/lib/python3.8/site-packages/grayskull/base/base_recipe.py",
    line 58, in __init__', '    self.update_all_recipe()', '  File "/usr/share/miniconda/envs/run_env/lib/python3.8/site-packages/grayskull/base/base_recipe.py",
    line 114, in update_all_recipe', '    self.refresh_section(section)', '  File
    "/usr/share/miniconda/envs/run_env/lib/python3.8/site-packages/grayskull/pypi/pypi.py",
    line 525, in refresh_section', '    metadata = self._get_metadata()', '  File
    "/usr/share/miniconda/envs/run_env/lib/python3.8/site-packages/grayskull/pypi/pypi.py",
    line 544, in _get_metadata', '    pypi_metadata = self._get_pypi_metadata(name,
    version)', '  File "/usr/share/miniconda/envs/run_env/lib/python3.8/site-packages/grayskull/pypi/pypi.py",
    line 673, in _get_pypi_metadata', '    raise requests.HTTPError(', 'requests.exceptions.HTTPError:
    It was not possible to recover PyPi metadata for pymt_child.', 'Error code: 404',
  '']
