exception: "HTTPSConnectionPool(host='spdx.org', port=443): Max retries exceeded with\
  \ url: /licenses/licenses.json (Caused by NewConnectionError('<urllib3.connection.HTTPSConnection\
  \ object at 0x7f6529939c50>: Failed to establish a new connection: [Errno -3] Temporary\
  \ failure in name resolution'))"
traceback: ['Traceback (most recent call last):', '  File "/usr/share/miniconda/envs/run_env/lib/python3.7/site-packages/urllib3/connection.py",
    line 160, in _new_conn', '    (self._dns_host, self.port), self.timeout, **extra_kw',
  '  File "/usr/share/miniconda/envs/run_env/lib/python3.7/site-packages/urllib3/util/connection.py",
    line 61, in create_connection', '    for res in socket.getaddrinfo(host, port,
    family, socket.SOCK_STREAM):', '  File "/usr/share/miniconda/envs/run_env/lib/python3.7/socket.py",
    line 752, in getaddrinfo', '    for res in _socket.getaddrinfo(host, port, family,
    type, proto, flags):', 'socket.gaierror: [Errno -3] Temporary failure in name
    resolution', '', 'During handling of the above exception, another exception occurred:',
  '', 'Traceback (most recent call last):', '  File "/usr/share/miniconda/envs/run_env/lib/python3.7/site-packages/urllib3/connectionpool.py",
    line 677, in urlopen', '    chunked=chunked,', '  File "/usr/share/miniconda/envs/run_env/lib/python3.7/site-packages/urllib3/connectionpool.py",
    line 381, in _make_request', '    self._validate_conn(conn)', '  File "/usr/share/miniconda/envs/run_env/lib/python3.7/site-packages/urllib3/connectionpool.py",
    line 978, in _validate_conn', '    conn.connect()', '  File "/usr/share/miniconda/envs/run_env/lib/python3.7/site-packages/urllib3/connection.py",
    line 309, in connect', '    conn = self._new_conn()', '  File "/usr/share/miniconda/envs/run_env/lib/python3.7/site-packages/urllib3/connection.py",
    line 172, in _new_conn', '    self, "Failed to establish a new connection: %s"
    % e', 'urllib3.exceptions.NewConnectionError: <urllib3.connection.HTTPSConnection
    object at 0x7f6529939c50>: Failed to establish a new connection: [Errno -3] Temporary
    failure in name resolution', '', 'During handling of the above exception, another
    exception occurred:', '', 'Traceback (most recent call last):', '  File "/usr/share/miniconda/envs/run_env/lib/python3.7/site-packages/requests/adapters.py",
    line 449, in send', '    timeout=timeout', '  File "/usr/share/miniconda/envs/run_env/lib/python3.7/site-packages/urllib3/connectionpool.py",
    line 727, in urlopen', '    method, url, error=e, _pool=self, _stacktrace=sys.exc_info()[2]',
  '  File "/usr/share/miniconda/envs/run_env/lib/python3.7/site-packages/urllib3/util/retry.py",
    line 439, in increment', '    raise MaxRetryError(_pool, url, error or ResponseError(cause))',
  "urllib3.exceptions.MaxRetryError: HTTPSConnectionPool(host='spdx.org', port=443):\
    \ Max retries exceeded with url: /licenses/licenses.json (Caused by NewConnectionError('<urllib3.connection.HTTPSConnection\
    \ object at 0x7f6529939c50>: Failed to establish a new connection: [Errno -3]\
    \ Temporary failure in name resolution'))", '', 'During handling of the above
    exception, another exception occurred:', '', 'Traceback (most recent call last):',
  '  File "/home/runner/work/autotick-bot/autotick-bot/cf-scripts/conda_forge_tick/audit.py",
    line 393, in main', '    deps = v["run"](fctx, ctx)', '  File "/home/runner/work/autotick-bot/autotick-bot/cf-scripts/conda_forge_tick/audit.py",
    line 91, in grayskull_audit_feedstock', '    download=False,', '  File "/usr/share/miniconda/envs/run_env/lib/python3.7/site-packages/grayskull/base/factory.py",
    line 23, in create_recipe', '    name, version, **kwargs', '  File "/usr/share/miniconda/envs/run_env/lib/python3.7/site-packages/grayskull/pypi/pypi.py",
    line 58, in __init__', '    super(PyPi, self).__init__(name=name, version=str(version)
    if version else None)', '  File "/usr/share/miniconda/envs/run_env/lib/python3.7/site-packages/grayskull/base/base_recipe.py",
    line 58, in __init__', '    self.update_all_recipe()', '  File "/usr/share/miniconda/envs/run_env/lib/python3.7/site-packages/grayskull/base/base_recipe.py",
    line 112, in update_all_recipe', '    self.refresh_section(section)', '  File
    "/usr/share/miniconda/envs/run_env/lib/python3.7/site-packages/grayskull/pypi/pypi.py",
    line 525, in refresh_section', '    metadata = self._get_metadata()', '  File
    "/usr/share/miniconda/envs/run_env/lib/python3.7/site-packages/grayskull/pypi/pypi.py",
    line 550, in _get_metadata', '    license_metadata = PyPi._discover_license(metadata)',
  '  File "/usr/share/miniconda/envs/run_env/lib/python3.7/site-packages/grayskull/pypi/pypi.py",
    line 650, in _discover_license', '    license_name_metadata=metadata.get("license"),',
  '  File "/usr/share/miniconda/envs/run_env/lib/python3.7/site-packages/grayskull/license/discovery.py",
    line 176, in search_license_file', '    license_name_metadata = get_short_license_id(license_name_metadata)',
  '  File "/usr/share/miniconda/envs/run_env/lib/python3.7/site-packages/grayskull/license/discovery.py",
    line 91, in get_short_license_id', '    recipe_license = match_license(name)',
  '  File "/usr/share/miniconda/envs/run_env/lib/python3.7/site-packages/grayskull/license/discovery.py",
    line 60, in match_license', '    all_licenses = get_all_licenses_from_spdx()',
  '  File "/usr/share/miniconda/envs/run_env/lib/python3.7/site-packages/grayskull/license/discovery.py",
    line 36, in get_all_licenses_from_spdx', '    response = requests.get(url="https://spdx.org/licenses/licenses.json",
    timeout=5)', '  File "/usr/share/miniconda/envs/run_env/lib/python3.7/site-packages/requests/api.py",
    line 76, in get', "    return request('get', url, params=params, **kwargs)", '  File
    "/usr/share/miniconda/envs/run_env/lib/python3.7/site-packages/requests/api.py",
    line 61, in request', '    return session.request(method=method, url=url, **kwargs)',
  '  File "/usr/share/miniconda/envs/run_env/lib/python3.7/site-packages/requests/sessions.py",
    line 530, in request', '    resp = self.send(prep, **send_kwargs)', '  File "/usr/share/miniconda/envs/run_env/lib/python3.7/site-packages/requests/sessions.py",
    line 643, in send', '    r = adapter.send(request, **kwargs)', '  File "/usr/share/miniconda/envs/run_env/lib/python3.7/site-packages/requests/adapters.py",
    line 516, in send', '    raise ConnectionError(e, request=request)', "requests.exceptions.ConnectionError:\
    \ HTTPSConnectionPool(host='spdx.org', port=443): Max retries exceeded with url:\
    \ /licenses/licenses.json (Caused by NewConnectionError('<urllib3.connection.HTTPSConnection\
    \ object at 0x7f6529939c50>: Failed to establish a new connection: [Errno -3]\
    \ Temporary failure in name resolution'))", '']
