{
 "exception":"failed to parse packages from exception: The following specifications were found to be incompatible with each other:\n\nOutput in format: Requested package -> Available versions\n\nPackage azure-mgmt-nspkg conflicts for:\nazure-mgmt-compute==0.20.1 -> azure-mgmt-common -> azure-mgmt-nspkg\nazure-mgmt-resource==0.20.1 -> azure-mgmt-common -> azure-mgmt-nspkg\nazure-mgmt-network==0.20.1 -> azure-mgmt-common -> azure-mgmt-nspkg\nazure-mgmt-storage==0.20.0 -> azure-mgmt-common -> azure-mgmt-nspkg\n\nPackage python conflicts for:\nazure-mgmt-storage==0.20.0 -> python[version='2.7.*|3.4.*|3.5.*']\nsetuptools -> python_abi=3.8[build=*_cp38] -> python[version='3.7.*|3.8.*']\npip -> python[version='2.7.*|3.5.*|3.6.*|>=2.7,<2.8.0a0|>=3.8,<3.9.0a0|>=3.6,<3.7.0a0|>=3.7,<3.8.0a0|>=3.5,<3.6.0a0|3.4.*']\nazure-mgmt-compute==0.20.1 -> python[version='2.7.*|3.4.*|3.5.*']\nsetuptools -> python[version='2.7.*|3.5.*|3.6.*|>=2.7,<2.8.0a0|>=3.6,<3.7.0a0|>=3.8,<3.9.0a0|>=3.7,<3.8.0a0|>=3.5,<3.6.0a0|3.4.*']\nazure-mgmt-resource==0.20.1 -> python[version='2.7.*|3.4.*|3.5.*']\nazure-mgmt-network==0.20.1 -> python[version='2.7.*|3.4.*|3.5.*']\n\nPackage setuptools conflicts for:\nsetuptools\npip -> setuptools\n\nPackage wheel conflicts for:\npip -> wheel\npython=3.7 -> pip -> wheel\n\nPackage python_abi conflicts for:\nsetuptools -> certifi[version='>=2016.9.26'] -> python_abi=2.7[build=*_cp27mu]\nsetuptools -> python_abi[version='3.6.*|3.6|3.8.*|3.7.*',build='*_cp37m|*_cp36m|*_pypy36_pp73|*_cp38']\npip -> python -> python_abi[version='3.6.*|3.6|3.8.*|3.7.*',build='*_cp37m|*_cp36m|*_pypy36_pp73|*_cp38']",
 "traceback":[
  "Traceback (most recent call last):",
  "  File \"/opt/conda/envs/run_env/lib/python3.7/site-packages/conda_build/environ.py\", line 764, in get_install_actions",
  "    actions = install_actions(prefix, index, specs, force=True)",
  "  File \"/opt/conda/envs/run_env/lib/python3.7/site-packages/conda/common/io.py\", line 88, in decorated",
  "    return f(*args, **kwds)",
  "  File \"/opt/conda/envs/run_env/lib/python3.7/site-packages/conda/plan.py\", line 474, in install_actions",
  "    txn = solver.solve_for_transaction(prune=prune, ignore_pinned=not pinned)",
  "  File \"/opt/conda/envs/run_env/lib/python3.7/site-packages/conda/core/solve.py\", line 117, in solve_for_transaction",
  "    should_retry_solve)",
  "  File \"/opt/conda/envs/run_env/lib/python3.7/site-packages/conda/core/solve.py\", line 158, in solve_for_diff",
  "    force_remove, should_retry_solve)",
  "  File \"/opt/conda/envs/run_env/lib/python3.7/site-packages/conda/core/solve.py\", line 281, in solve_final_state",
  "    ssc = self._run_sat(ssc)",
  "  File \"/opt/conda/envs/run_env/lib/python3.7/site-packages/conda/common/io.py\", line 88, in decorated",
  "    return f(*args, **kwds)",
  "  File \"/opt/conda/envs/run_env/lib/python3.7/site-packages/conda/core/solve.py\", line 808, in _run_sat",
  "    should_retry_solve=ssc.should_retry_solve",
  "  File \"/opt/conda/envs/run_env/lib/python3.7/site-packages/conda/common/io.py\", line 88, in decorated",
  "    return f(*args, **kwds)",
  "  File \"/opt/conda/envs/run_env/lib/python3.7/site-packages/conda/resolve.py\", line 1318, in solve",
  "    self.find_conflicts(specs, specs_to_add, history_specs)",
  "  File \"/opt/conda/envs/run_env/lib/python3.7/site-packages/conda/resolve.py\", line 351, in find_conflicts",
  "    raise UnsatisfiableError(bad_deps, strict=strict_channel_priority)",
  "conda.exceptions.UnsatisfiableError: The following specifications were found to be incompatible with each other:",
  "",
  "Output in format: Requested package -> Available versions",
  "",
  "Package azure-mgmt-nspkg conflicts for:",
  "azure-mgmt-compute==0.20.1 -> azure-mgmt-common -> azure-mgmt-nspkg",
  "azure-mgmt-resource==0.20.1 -> azure-mgmt-common -> azure-mgmt-nspkg",
  "azure-mgmt-network==0.20.1 -> azure-mgmt-common -> azure-mgmt-nspkg",
  "azure-mgmt-storage==0.20.0 -> azure-mgmt-common -> azure-mgmt-nspkg",
  "",
  "Package python conflicts for:",
  "azure-mgmt-storage==0.20.0 -> python[version='2.7.*|3.4.*|3.5.*']",
  "setuptools -> python_abi=3.8[build=*_cp38] -> python[version='3.7.*|3.8.*']",
  "pip -> python[version='2.7.*|3.5.*|3.6.*|>=2.7,<2.8.0a0|>=3.8,<3.9.0a0|>=3.6,<3.7.0a0|>=3.7,<3.8.0a0|>=3.5,<3.6.0a0|3.4.*']",
  "azure-mgmt-compute==0.20.1 -> python[version='2.7.*|3.4.*|3.5.*']",
  "setuptools -> python[version='2.7.*|3.5.*|3.6.*|>=2.7,<2.8.0a0|>=3.6,<3.7.0a0|>=3.8,<3.9.0a0|>=3.7,<3.8.0a0|>=3.5,<3.6.0a0|3.4.*']",
  "azure-mgmt-resource==0.20.1 -> python[version='2.7.*|3.4.*|3.5.*']",
  "azure-mgmt-network==0.20.1 -> python[version='2.7.*|3.4.*|3.5.*']",
  "",
  "Package setuptools conflicts for:",
  "setuptools",
  "pip -> setuptools",
  "",
  "Package wheel conflicts for:",
  "pip -> wheel",
  "python=3.7 -> pip -> wheel",
  "",
  "Package python_abi conflicts for:",
  "setuptools -> certifi[version='>=2016.9.26'] -> python_abi=2.7[build=*_cp27mu]",
  "setuptools -> python_abi[version='3.6.*|3.6|3.8.*|3.7.*',build='*_cp37m|*_cp36m|*_pypy36_pp73|*_cp38']",
  "pip -> python -> python_abi[version='3.6.*|3.6|3.8.*|3.7.*',build='*_cp37m|*_cp36m|*_pypy36_pp73|*_cp38']",
  "",
  "During handling of the above exception, another exception occurred:",
  "",
  "Traceback (most recent call last):",
  "  File \"/root/repo/cf-scripts/conda_forge_tick/audit.py\", line 67, in main",
  "    deps = audit_feedstock(fctx, ctx)",
  "  File \"/root/repo/cf-scripts/conda_forge_tick/audit.py\", line 30, in audit_feedstock",
  "    cb_work_dir = _get_source_code(recipe_dir)",
  "  File \"/root/repo/cf-scripts/conda_forge_tick/migrators/core.py\", line 68, in _get_source_code",
  "    md = render(recipe_dir, config=Config(**CB_CONFIG))",
  "  File \"/opt/conda/envs/run_env/lib/python3.7/site-packages/conda_build/api.py\", line 52, in render",
  "    bypass_env_check=bypass_env_check):",
  "  File \"/opt/conda/envs/run_env/lib/python3.7/site-packages/conda_build/metadata.py\", line 2054, in get_output_metadata_set",
  "    bypass_env_check=bypass_env_check)",
  "  File \"/opt/conda/envs/run_env/lib/python3.7/site-packages/conda_build/metadata.py\", line 727, in finalize_outputs_pass",
  "    permit_unsatisfiable_variants=permit_unsatisfiable_variants)",
  "  File \"/opt/conda/envs/run_env/lib/python3.7/site-packages/conda_build/render.py\", line 538, in finalize_metadata",
  "    exclude_pattern)",
  "  File \"/opt/conda/envs/run_env/lib/python3.7/site-packages/conda_build/render.py\", line 412, in add_upstream_pins",
  "    permit_unsatisfiable_variants, exclude_pattern)",
  "  File \"/opt/conda/envs/run_env/lib/python3.7/site-packages/conda_build/render.py\", line 378, in _read_upstream_pin_files",
  "    permit_unsatisfiable_variants=permit_unsatisfiable_variants)",
  "  File \"/opt/conda/envs/run_env/lib/python3.7/site-packages/conda_build/render.py\", line 154, in get_env_dependencies",
  "    channel_urls=tuple(m.config.channel_urls))",
  "  File \"/opt/conda/envs/run_env/lib/python3.7/site-packages/conda_build/environ.py\", line 766, in get_install_actions",
  "    raise DependencyNeedsBuildingError(exc, subdir=subdir)",
  "  File \"/opt/conda/envs/run_env/lib/python3.7/site-packages/conda_build/exceptions.py\", line 78, in __init__",
  "    \" {}\".format(str(conda_exception)))",
  "RuntimeError: failed to parse packages from exception: The following specifications were found to be incompatible with each other:",
  "",
  "Output in format: Requested package -> Available versions",
  "",
  "Package azure-mgmt-nspkg conflicts for:",
  "azure-mgmt-compute==0.20.1 -> azure-mgmt-common -> azure-mgmt-nspkg",
  "azure-mgmt-resource==0.20.1 -> azure-mgmt-common -> azure-mgmt-nspkg",
  "azure-mgmt-network==0.20.1 -> azure-mgmt-common -> azure-mgmt-nspkg",
  "azure-mgmt-storage==0.20.0 -> azure-mgmt-common -> azure-mgmt-nspkg",
  "",
  "Package python conflicts for:",
  "azure-mgmt-storage==0.20.0 -> python[version='2.7.*|3.4.*|3.5.*']",
  "setuptools -> python_abi=3.8[build=*_cp38] -> python[version='3.7.*|3.8.*']",
  "pip -> python[version='2.7.*|3.5.*|3.6.*|>=2.7,<2.8.0a0|>=3.8,<3.9.0a0|>=3.6,<3.7.0a0|>=3.7,<3.8.0a0|>=3.5,<3.6.0a0|3.4.*']",
  "azure-mgmt-compute==0.20.1 -> python[version='2.7.*|3.4.*|3.5.*']",
  "setuptools -> python[version='2.7.*|3.5.*|3.6.*|>=2.7,<2.8.0a0|>=3.6,<3.7.0a0|>=3.8,<3.9.0a0|>=3.7,<3.8.0a0|>=3.5,<3.6.0a0|3.4.*']",
  "azure-mgmt-resource==0.20.1 -> python[version='2.7.*|3.4.*|3.5.*']",
  "azure-mgmt-network==0.20.1 -> python[version='2.7.*|3.4.*|3.5.*']",
  "",
  "Package setuptools conflicts for:",
  "setuptools",
  "pip -> setuptools",
  "",
  "Package wheel conflicts for:",
  "pip -> wheel",
  "python=3.7 -> pip -> wheel",
  "",
  "Package python_abi conflicts for:",
  "setuptools -> certifi[version='>=2016.9.26'] -> python_abi=2.7[build=*_cp27mu]",
  "setuptools -> python_abi[version='3.6.*|3.6|3.8.*|3.7.*',build='*_cp37m|*_cp36m|*_pypy36_pp73|*_cp38']",
  "pip -> python -> python_abi[version='3.6.*|3.6|3.8.*|3.7.*',build='*_cp37m|*_cp36m|*_pypy36_pp73|*_cp38']",
  ""
 ]
}