{
 "exception":"failed to parse packages from exception: The following specifications were found to be incompatible with each other:\n\nOutput in format: Requested package -> Available versions\n\nPackage certifi conflicts for:\nsetuptools -> certifi[version='>=2016.09|>=2016.9.26']\npip -> setuptools -> certifi[version='>=2016.09|>=2016.9.26']\n\nPackage blis conflicts for:\nnumpy=1.11 -> libblas[version='>=3.8.0,<4.0a0'] -> blis[version='0.5.1.*|>=0.5.2,<0.5.3.0a0|>=0.6.0,<0.6.1.0a0|>=0.6.1,<0.6.2.0a0']\ncasacore[version='>=3.2.*'] -> libblas[version='>=3.8.0,<4.0a0'] -> blis[version='0.5.1.*|>=0.5.2,<0.5.3.0a0|>=0.6.0,<0.6.1.0a0|>=0.6.1,<0.6.2.0a0']\n\nPackage numpy conflicts for:\nboost -> py-boost==1.71.0=py38h962f231_0 -> numpy[version='>=1.11.3,<2.0a0']\ncasacore[version='>=3.2.*'] -> numpy[version='>=1.14.6,<2.0a0']\nboost -> numpy[version='1.11.*|1.12.*|1.13.*|>=1.11|>=1.14.6,<2.0a0|>=1.9.3,<2.0a0|>=1.8|>=1.9|>=1.7']\nnumpy=1.11\n\nPackage setuptools conflicts for:\npython=3.7 -> pip -> setuptools\npip -> setuptools\nsetuptools\n\nPackage ca-certificates conflicts for:\npip -> python -> ca-certificates\npython=3.7 -> openssl[version='>=1.1.1e,<1.1.2a'] -> ca-certificates\nboost -> python[version='>=2.7,<2.8.0a0'] -> ca-certificates\nnumpy=1.11 -> python[version='>=2.7,<2.8.0a0'] -> ca-certificates\nsetuptools -> python[version='>=2.7,<2.8.0a0'] -> ca-certificates\n\nPackage _openmp_mutex conflicts for:\nnumpy=1.11 -> libgcc-ng[version='>=7.3.0'] -> _openmp_mutex[version='*|>=4.5',build=*_llvm]\nboost -> libgcc-ng[version='>=7.3.0'] -> _openmp_mutex[version='>=4.5']\ncasacore[version='>=3.2.*'] -> libgcc-ng[version='>=7.3.0'] -> _openmp_mutex[version='>=4.5']\npython=3.7 -> libgcc-ng[version='>=7.3.0'] -> _openmp_mutex[version='>=4.5']\n\nPackage python conflicts for:\npip -> python[version='2.7.*|3.5.*|3.6.*|>=2.7,<2.8.0a0|>=3.8,<3.9.0a0|>=3.6,<3.7.0a0|>=3.7,<3.8.0a0|>=3.5,<3.6.0a0|3.4.*']\nboost -> python[version='2.7.*|3.5.*|3.6.*|>=2.7,<2.8.0a0|>=3.6,<3.7.0a0|>=3.8,<3.9.0a0|>=3.7,<3.8.0a0|>=3.5,<3.6.0a0|3.4.*']\npython=3.7\ncasacore[version='>=3.2.*'] -> python[version='>=3.6,<3.7.0a0|>=3.7,<3.8.0a0|>=3.8,<3.9.0a0']\nsetuptools -> python_abi=3.8[build=*_cp38] -> python[version='3.7.*|3.8.*']\nsetuptools -> python[version='2.7.*|3.5.*|3.6.*|>=2.7,<2.8.0a0|>=3.6,<3.7.0a0|>=3.8,<3.9.0a0|>=3.7,<3.8.0a0|>=3.5,<3.6.0a0|3.4.*']\ncasacore[version='>=3.2.*'] -> boost[version='>=1.72.0,<1.72.1.0a0'] -> python[version='3.6.*|3.7.*|>=2.7,<2.8.0a0|>=3.5,<3.6.0a0|3.8.*']\n\nPackage pypy3.6 conflicts for:\nsetuptools -> python[version='>=3.6,<3.7.0a0'] -> pypy3.6[version='7.3.*|7.3.0.*|7.3.1.*']\nnumpy=1.11 -> python[version='>=3.6,<3.7.0a0'] -> pypy3.6[version='7.3.0.*|7.3.1.*']\nboost -> python[version='>=3.6,<3.7.0a0'] -> pypy3.6[version='7.3.0.*|7.3.1.*']\ncasacore[version='>=3.2.*'] -> python[version='>=3.6,<3.7.0a0'] -> pypy3.6[version='7.3.0.*|7.3.1.*']\npip -> python -> pypy3.6[version='7.3.0.*|7.3.1.*']\n\nPackage python_abi conflicts for:\ncasacore[version='>=3.2.*'] -> python_abi[version='3.6.*|3.7.*|3.8.*',build='*_cp36m|*_cp38|*_cp37m']\ncasacore[version='>=3.2.*'] -> numpy[version='>=1.14.6,<2.0a0'] -> python_abi==3.6[build=*_pypy36_pp73]\n\nPackage wheel conflicts for:\npython=3.7 -> pip -> wheel\npip -> wheel\n\nPackage boost conflicts for:\ncasacore[version='>=3.2.*'] -> boost[version='>=1.72.0,<1.72.1.0a0']\nboost",
 "traceback":[
  "Traceback (most recent call last):",
  "  File \"/opt/conda/envs/run_env/lib/python3.7/site-packages/conda_build/environ.py\", line 764, in get_install_actions",
  "    actions = install_actions(prefix, index, specs, force=True)",
  "  File \"/opt/conda/envs/run_env/lib/python3.7/site-packages/conda/common/io.py\", line 88, in decorated",
  "    return f(*args, **kwds)",
  "  File \"/opt/conda/envs/run_env/lib/python3.7/site-packages/conda/plan.py\", line 474, in install_actions",
  "    txn = solver.solve_for_transaction(prune=prune, ignore_pinned=not pinned)",
  "  File \"/opt/conda/envs/run_env/lib/python3.7/site-packages/conda/core/solve.py\", line 117, in solve_for_transaction",
  "    should_retry_solve)",
  "  File \"/opt/conda/envs/run_env/lib/python3.7/site-packages/conda/core/solve.py\", line 158, in solve_for_diff",
  "    force_remove, should_retry_solve)",
  "  File \"/opt/conda/envs/run_env/lib/python3.7/site-packages/conda/core/solve.py\", line 281, in solve_final_state",
  "    ssc = self._run_sat(ssc)",
  "  File \"/opt/conda/envs/run_env/lib/python3.7/site-packages/conda/common/io.py\", line 88, in decorated",
  "    return f(*args, **kwds)",
  "  File \"/opt/conda/envs/run_env/lib/python3.7/site-packages/conda/core/solve.py\", line 808, in _run_sat",
  "    should_retry_solve=ssc.should_retry_solve",
  "  File \"/opt/conda/envs/run_env/lib/python3.7/site-packages/conda/common/io.py\", line 88, in decorated",
  "    return f(*args, **kwds)",
  "  File \"/opt/conda/envs/run_env/lib/python3.7/site-packages/conda/resolve.py\", line 1318, in solve",
  "    self.find_conflicts(specs, specs_to_add, history_specs)",
  "  File \"/opt/conda/envs/run_env/lib/python3.7/site-packages/conda/resolve.py\", line 351, in find_conflicts",
  "    raise UnsatisfiableError(bad_deps, strict=strict_channel_priority)",
  "conda.exceptions.UnsatisfiableError: The following specifications were found to be incompatible with each other:",
  "",
  "Output in format: Requested package -> Available versions",
  "",
  "Package certifi conflicts for:",
  "setuptools -> certifi[version='>=2016.09|>=2016.9.26']",
  "pip -> setuptools -> certifi[version='>=2016.09|>=2016.9.26']",
  "",
  "Package blis conflicts for:",
  "numpy=1.11 -> libblas[version='>=3.8.0,<4.0a0'] -> blis[version='0.5.1.*|>=0.5.2,<0.5.3.0a0|>=0.6.0,<0.6.1.0a0|>=0.6.1,<0.6.2.0a0']",
  "casacore[version='>=3.2.*'] -> libblas[version='>=3.8.0,<4.0a0'] -> blis[version='0.5.1.*|>=0.5.2,<0.5.3.0a0|>=0.6.0,<0.6.1.0a0|>=0.6.1,<0.6.2.0a0']",
  "",
  "Package numpy conflicts for:",
  "boost -> py-boost==1.71.0=py38h962f231_0 -> numpy[version='>=1.11.3,<2.0a0']",
  "casacore[version='>=3.2.*'] -> numpy[version='>=1.14.6,<2.0a0']",
  "boost -> numpy[version='1.11.*|1.12.*|1.13.*|>=1.11|>=1.14.6,<2.0a0|>=1.9.3,<2.0a0|>=1.8|>=1.9|>=1.7']",
  "numpy=1.11",
  "",
  "Package setuptools conflicts for:",
  "python=3.7 -> pip -> setuptools",
  "pip -> setuptools",
  "setuptools",
  "",
  "Package ca-certificates conflicts for:",
  "pip -> python -> ca-certificates",
  "python=3.7 -> openssl[version='>=1.1.1e,<1.1.2a'] -> ca-certificates",
  "boost -> python[version='>=2.7,<2.8.0a0'] -> ca-certificates",
  "numpy=1.11 -> python[version='>=2.7,<2.8.0a0'] -> ca-certificates",
  "setuptools -> python[version='>=2.7,<2.8.0a0'] -> ca-certificates",
  "",
  "Package _openmp_mutex conflicts for:",
  "numpy=1.11 -> libgcc-ng[version='>=7.3.0'] -> _openmp_mutex[version='*|>=4.5',build=*_llvm]",
  "boost -> libgcc-ng[version='>=7.3.0'] -> _openmp_mutex[version='>=4.5']",
  "casacore[version='>=3.2.*'] -> libgcc-ng[version='>=7.3.0'] -> _openmp_mutex[version='>=4.5']",
  "python=3.7 -> libgcc-ng[version='>=7.3.0'] -> _openmp_mutex[version='>=4.5']",
  "",
  "Package python conflicts for:",
  "pip -> python[version='2.7.*|3.5.*|3.6.*|>=2.7,<2.8.0a0|>=3.8,<3.9.0a0|>=3.6,<3.7.0a0|>=3.7,<3.8.0a0|>=3.5,<3.6.0a0|3.4.*']",
  "boost -> python[version='2.7.*|3.5.*|3.6.*|>=2.7,<2.8.0a0|>=3.6,<3.7.0a0|>=3.8,<3.9.0a0|>=3.7,<3.8.0a0|>=3.5,<3.6.0a0|3.4.*']",
  "python=3.7",
  "casacore[version='>=3.2.*'] -> python[version='>=3.6,<3.7.0a0|>=3.7,<3.8.0a0|>=3.8,<3.9.0a0']",
  "setuptools -> python_abi=3.8[build=*_cp38] -> python[version='3.7.*|3.8.*']",
  "setuptools -> python[version='2.7.*|3.5.*|3.6.*|>=2.7,<2.8.0a0|>=3.6,<3.7.0a0|>=3.8,<3.9.0a0|>=3.7,<3.8.0a0|>=3.5,<3.6.0a0|3.4.*']",
  "casacore[version='>=3.2.*'] -> boost[version='>=1.72.0,<1.72.1.0a0'] -> python[version='3.6.*|3.7.*|>=2.7,<2.8.0a0|>=3.5,<3.6.0a0|3.8.*']",
  "",
  "Package pypy3.6 conflicts for:",
  "setuptools -> python[version='>=3.6,<3.7.0a0'] -> pypy3.6[version='7.3.*|7.3.0.*|7.3.1.*']",
  "numpy=1.11 -> python[version='>=3.6,<3.7.0a0'] -> pypy3.6[version='7.3.0.*|7.3.1.*']",
  "boost -> python[version='>=3.6,<3.7.0a0'] -> pypy3.6[version='7.3.0.*|7.3.1.*']",
  "casacore[version='>=3.2.*'] -> python[version='>=3.6,<3.7.0a0'] -> pypy3.6[version='7.3.0.*|7.3.1.*']",
  "pip -> python -> pypy3.6[version='7.3.0.*|7.3.1.*']",
  "",
  "Package python_abi conflicts for:",
  "casacore[version='>=3.2.*'] -> python_abi[version='3.6.*|3.7.*|3.8.*',build='*_cp36m|*_cp38|*_cp37m']",
  "casacore[version='>=3.2.*'] -> numpy[version='>=1.14.6,<2.0a0'] -> python_abi==3.6[build=*_pypy36_pp73]",
  "",
  "Package wheel conflicts for:",
  "python=3.7 -> pip -> wheel",
  "pip -> wheel",
  "",
  "Package boost conflicts for:",
  "casacore[version='>=3.2.*'] -> boost[version='>=1.72.0,<1.72.1.0a0']",
  "boost",
  "",
  "During handling of the above exception, another exception occurred:",
  "",
  "Traceback (most recent call last):",
  "  File \"/root/repo/cf-scripts/conda_forge_tick/audit.py\", line 67, in main",
  "    deps = audit_feedstock(fctx, ctx)",
  "  File \"/root/repo/cf-scripts/conda_forge_tick/audit.py\", line 30, in audit_feedstock",
  "    cb_work_dir = _get_source_code(recipe_dir)",
  "  File \"/root/repo/cf-scripts/conda_forge_tick/migrators/core.py\", line 68, in _get_source_code",
  "    md = render(recipe_dir, config=Config(**CB_CONFIG))",
  "  File \"/opt/conda/envs/run_env/lib/python3.7/site-packages/conda_build/api.py\", line 45, in render",
  "    permit_unsatisfiable_variants=permit_unsatisfiable_variants)",
  "  File \"/opt/conda/envs/run_env/lib/python3.7/site-packages/conda_build/render.py\", line 830, in render_recipe",
  "    allow_no_other_outputs=True, bypass_env_check=bypass_env_check)",
  "  File \"/opt/conda/envs/run_env/lib/python3.7/site-packages/conda_build/render.py\", line 736, in distribute_variants",
  "    bypass_env_check=bypass_env_check)",
  "  File \"/opt/conda/envs/run_env/lib/python3.7/site-packages/conda_build/metadata.py\", line 1023, in parse_until_resolved",
  "    bypass_env_check=bypass_env_check)",
  "  File \"/opt/conda/envs/run_env/lib/python3.7/site-packages/conda_build/metadata.py\", line 945, in parse_again",
  "    bypass_env_check=bypass_env_check),",
  "  File \"/opt/conda/envs/run_env/lib/python3.7/site-packages/conda_build/metadata.py\", line 1534, in _get_contents",
  "    rendered = template.render(environment=env)",
  "  File \"/opt/conda/envs/run_env/lib/python3.7/site-packages/jinja2/environment.py\", line 1090, in render",
  "    self.environment.handle_exception()",
  "  File \"/opt/conda/envs/run_env/lib/python3.7/site-packages/jinja2/environment.py\", line 832, in handle_exception",
  "    reraise(*rewrite_traceback_stack(source=source))",
  "  File \"/opt/conda/envs/run_env/lib/python3.7/site-packages/jinja2/_compat.py\", line 28, in reraise",
  "    raise value.with_traceback(tb)",
  "  File \"/root/repo/cf-graph/feedstocks/python-casacore-feedstock/recipe/meta.yaml\", line 29, in top-level template code",
  "    run:",
  "  File \"/opt/conda/envs/run_env/lib/python3.7/site-packages/conda_build/jinja_context.py\", line 230, in pin_compatible",
  "    pins, _, _ = get_env_dependencies(m, 'host', m.config.variant)",
  "  File \"/opt/conda/envs/run_env/lib/python3.7/site-packages/conda_build/render.py\", line 154, in get_env_dependencies",
  "    channel_urls=tuple(m.config.channel_urls))",
  "  File \"/opt/conda/envs/run_env/lib/python3.7/site-packages/conda_build/environ.py\", line 766, in get_install_actions",
  "    raise DependencyNeedsBuildingError(exc, subdir=subdir)",
  "  File \"/opt/conda/envs/run_env/lib/python3.7/site-packages/conda_build/exceptions.py\", line 78, in __init__",
  "    \" {}\".format(str(conda_exception)))",
  "RuntimeError: failed to parse packages from exception: The following specifications were found to be incompatible with each other:",
  "",
  "Output in format: Requested package -> Available versions",
  "",
  "Package certifi conflicts for:",
  "setuptools -> certifi[version='>=2016.09|>=2016.9.26']",
  "pip -> setuptools -> certifi[version='>=2016.09|>=2016.9.26']",
  "",
  "Package blis conflicts for:",
  "numpy=1.11 -> libblas[version='>=3.8.0,<4.0a0'] -> blis[version='0.5.1.*|>=0.5.2,<0.5.3.0a0|>=0.6.0,<0.6.1.0a0|>=0.6.1,<0.6.2.0a0']",
  "casacore[version='>=3.2.*'] -> libblas[version='>=3.8.0,<4.0a0'] -> blis[version='0.5.1.*|>=0.5.2,<0.5.3.0a0|>=0.6.0,<0.6.1.0a0|>=0.6.1,<0.6.2.0a0']",
  "",
  "Package numpy conflicts for:",
  "boost -> py-boost==1.71.0=py38h962f231_0 -> numpy[version='>=1.11.3,<2.0a0']",
  "casacore[version='>=3.2.*'] -> numpy[version='>=1.14.6,<2.0a0']",
  "boost -> numpy[version='1.11.*|1.12.*|1.13.*|>=1.11|>=1.14.6,<2.0a0|>=1.9.3,<2.0a0|>=1.8|>=1.9|>=1.7']",
  "numpy=1.11",
  "",
  "Package setuptools conflicts for:",
  "python=3.7 -> pip -> setuptools",
  "pip -> setuptools",
  "setuptools",
  "",
  "Package ca-certificates conflicts for:",
  "pip -> python -> ca-certificates",
  "python=3.7 -> openssl[version='>=1.1.1e,<1.1.2a'] -> ca-certificates",
  "boost -> python[version='>=2.7,<2.8.0a0'] -> ca-certificates",
  "numpy=1.11 -> python[version='>=2.7,<2.8.0a0'] -> ca-certificates",
  "setuptools -> python[version='>=2.7,<2.8.0a0'] -> ca-certificates",
  "",
  "Package _openmp_mutex conflicts for:",
  "numpy=1.11 -> libgcc-ng[version='>=7.3.0'] -> _openmp_mutex[version='*|>=4.5',build=*_llvm]",
  "boost -> libgcc-ng[version='>=7.3.0'] -> _openmp_mutex[version='>=4.5']",
  "casacore[version='>=3.2.*'] -> libgcc-ng[version='>=7.3.0'] -> _openmp_mutex[version='>=4.5']",
  "python=3.7 -> libgcc-ng[version='>=7.3.0'] -> _openmp_mutex[version='>=4.5']",
  "",
  "Package python conflicts for:",
  "pip -> python[version='2.7.*|3.5.*|3.6.*|>=2.7,<2.8.0a0|>=3.8,<3.9.0a0|>=3.6,<3.7.0a0|>=3.7,<3.8.0a0|>=3.5,<3.6.0a0|3.4.*']",
  "boost -> python[version='2.7.*|3.5.*|3.6.*|>=2.7,<2.8.0a0|>=3.6,<3.7.0a0|>=3.8,<3.9.0a0|>=3.7,<3.8.0a0|>=3.5,<3.6.0a0|3.4.*']",
  "python=3.7",
  "casacore[version='>=3.2.*'] -> python[version='>=3.6,<3.7.0a0|>=3.7,<3.8.0a0|>=3.8,<3.9.0a0']",
  "setuptools -> python_abi=3.8[build=*_cp38] -> python[version='3.7.*|3.8.*']",
  "setuptools -> python[version='2.7.*|3.5.*|3.6.*|>=2.7,<2.8.0a0|>=3.6,<3.7.0a0|>=3.8,<3.9.0a0|>=3.7,<3.8.0a0|>=3.5,<3.6.0a0|3.4.*']",
  "casacore[version='>=3.2.*'] -> boost[version='>=1.72.0,<1.72.1.0a0'] -> python[version='3.6.*|3.7.*|>=2.7,<2.8.0a0|>=3.5,<3.6.0a0|3.8.*']",
  "",
  "Package pypy3.6 conflicts for:",
  "setuptools -> python[version='>=3.6,<3.7.0a0'] -> pypy3.6[version='7.3.*|7.3.0.*|7.3.1.*']",
  "numpy=1.11 -> python[version='>=3.6,<3.7.0a0'] -> pypy3.6[version='7.3.0.*|7.3.1.*']",
  "boost -> python[version='>=3.6,<3.7.0a0'] -> pypy3.6[version='7.3.0.*|7.3.1.*']",
  "casacore[version='>=3.2.*'] -> python[version='>=3.6,<3.7.0a0'] -> pypy3.6[version='7.3.0.*|7.3.1.*']",
  "pip -> python -> pypy3.6[version='7.3.0.*|7.3.1.*']",
  "",
  "Package python_abi conflicts for:",
  "casacore[version='>=3.2.*'] -> python_abi[version='3.6.*|3.7.*|3.8.*',build='*_cp36m|*_cp38|*_cp37m']",
  "casacore[version='>=3.2.*'] -> numpy[version='>=1.14.6,<2.0a0'] -> python_abi==3.6[build=*_pypy36_pp73]",
  "",
  "Package wheel conflicts for:",
  "python=3.7 -> pip -> wheel",
  "pip -> wheel",
  "",
  "Package boost conflicts for:",
  "casacore[version='>=3.2.*'] -> boost[version='>=1.72.0,<1.72.1.0a0']",
  "boost",
  ""
 ]
}