{
 "exception":"Destination path '/opt/conda/envs/run_env/conda-bld/root_1591811277258/work/root-source/proof/proof' already exists",
 "traceback":[
  "Traceback (most recent call last):",
  "  File \"/root/repo/cf-scripts/conda_forge_tick/audit.py\", line 68, in main",
  "    deps = audit_feedstock(fctx, ctx)",
  "  File \"/root/repo/cf-scripts/conda_forge_tick/audit.py\", line 30, in audit_feedstock",
  "    cb_work_dir = _get_source_code(recipe_dir)",
  "  File \"/root/repo/cf-scripts/conda_forge_tick/migrators/core.py\", line 71, in _get_source_code",
  "    return provide(md)",
  "  File \"/opt/conda/envs/run_env/lib/python3.7/site-packages/conda_build/source.py\", line 654, in provide",
  "    timeout=metadata.config.timeout, locking=metadata.config.locking)",
  "  File \"/opt/conda/envs/run_env/lib/python3.7/site-packages/conda_build/source.py\", line 166, in unpack",
  "    shutil.move(os.path.join(tmpdir, f), os.path.join(src_dir, f))",
  "  File \"/opt/conda/envs/run_env/lib/python3.7/shutil.py\", line 564, in move",
  "    raise Error(\"Destination path '%s' already exists\" % real_dst)",
  "shutil.Error: Destination path '/opt/conda/envs/run_env/conda-bld/root_1591811277258/work/root-source/proof/proof' already exists",
  ""
 ]
}